Workbook

Sheet Cost Build-up
A1: COST BUILD-UP / RATE BREAKDOWN — Sections 3, 4 & 5
A2: Project: CAG Workers Dormitory | Basis: Singapore 2026 D&B Rates | All amounts in S$
A4: SECTION 3.2 — DORMITORY BLOCKS (8 nos × 4 storeys, GFA 47,420 m²)
A5: BOQ Ref | B5: Description / Sub-component | C5: Qty | D5: Unit | E5: Rate (S$) | F5: Amount (S$) | G5: Remarks
A6: 3.2/1.1 | B6: Substructure — Earthworks & Waterproofing (8 blocks)
B7: Bituminous WP membrane to slab on grade, 1.5mm SBS | C7: 11856 | D7: m² | E7: 30 | F7: =C7*E7 -> 355680 | G7: Footprint 1,482 m² × 8 blocks
B8: Anti-termite chemical treatment to soil | C8: 11856 | D8: m² | E8: 22.5 | F8: =C8*E8 -> 266760 | G8: TM4083 compliant
B9: Excavation to reduced level, average 1.2m depth | C9: 14227 | D9: m³ | E9: 28 | F9: =C9*E9 -> 398356 | G9: Mech excavation incl spoil to dump
B10: Backfill with approved granular material | C10: 4742 | D10: m³ | E10: 35 | F10: =C10*E10 -> 165970 | G10: Compacted in 150mm layers
B11: Cart away surplus to off-site disposal | C11: 9485 | D11: m³ | E11: 45 | F11: =C11*E11 -> 426825 | G11: Lorry transport + tipping fee
B12: Subtotal — Substructure Earthworks (×2 phases) | F12: =SUM(F6:F11) -> 1613591
A13: 3.2/1.2 | B13: Raft Foundation (8 blocks)
B14: Lean concrete blinding 50mm thick, Grade C20 | C14: 593 | D14: m³ | E14: 280 | F14: =C14*E14 -> 166040 | G14: 11,856 m² × 0.05m
B15: Hardcore bedding 150mm compacted | C15: 1778 | D15: m³ | E15: 90 | F15: =C15*E15 -> 160020 | G15: Crushed stone 40mm down
B16: Reinforced concrete raft slab, 600mm thick, Grade C40 | C16: 7114 | D16: m³ | E16: 380 | F16: =C16*E16 -> 2703320 | G16: Ready-mix incl pump
B17: Sawn formwork to raft edges | C17: 4800 | D17: m² | E17: 65 | F17: =C17*E17 -> 312000 | G17: Perimeter & construction joints
B18: High-yield reinforcement T20-T25, BS500B | C18: 854 | D18: tonne | E18: 1750 | F18: =C18*E18 -> 1494500 | G18: 120 kg/m³ raft slab
B19: Plate load test | C19: 16 | D19: no | E19: 1800 | F19: =C19*E19 -> 28800 | G19: 2 tests per block
B20: Subtotal — Raft Foundation (×2 phases) | F20: =SUM(F13:F19) -> 4864680
A21: 3.2/2.1 | B21: Superstructure — Frame (8 blocks × 4 storeys)
B22: Reinforced concrete columns C40 | C22: 1422 | D22: m³ | E22: 580 | F22: =C22*E22 -> 824760 | G22: ~30 m³/storey × 4 × 8 blocks
B23: Formwork to columns | C23: 9484 | D23: m² | E23: 70 | F23: =C23*E23 -> 663880 | G23: 8x perimeter coverage
B24: Reinforcement to columns T20-T32 | C24: 256 | D24: tonne | E24: 1900 | F24: =C24*E24 -> 486400 | G24: 180 kg/m³
B25: RC beams C40 | C25: 1896 | D25: m³ | E25: 620 | F25: =C25*E25 -> 1175520 | G25: Tie beams + main beams
B26: Formwork to beams (soffit + sides) | C26: 12640 | D26: m² | E26: 80 | F26: =C26*E26 -> 1011200 | G26: Includes propping
B27: Reinforcement to beams T16-T25 | C27: 380 | D27: tonne | E27: 1850 | F27: =C27*E27 -> 703000 | G27: 200 kg/m³
B28: Subtotal — Superstructure Frame (×2 phases) | F28: =SUM(F21:F27) -> 4864760
A29: 3.2/2.2 | B29: Upper Floor Slabs (3 elevated levels × 8 blocks)
B30: RC slab 175mm thick, C40 | C30: 6224 | D30: m³ | E30: 410 | F30: =C30*E30 -> 2551840 | G30: 1,482 m² × 3 floors × 8 × 0.175m
B31: Formwork & propping to soffit | C31: 35568 | D31: m² | E31: 55 | F31: =C31*E31 -> 1956240 | G31: Hire system formwork
B32: Reinforcement to slabs T10-T16 | C32: 747 | D32: tonne | E32: 1800 | F32: =C32*E32 -> 1344600 | G32: 120 kg/m³
B33: Cast iron rainwater pipes DN100 to corridor | C33: 960 | D33: m | E33: 175 | F33: =C33*E33 -> 168000 | G33: 30m × 8 blocks × 4 floors
B34: Floor outlets stainless steel 100mm | C34: 384 | D34: no | E34: 220 | F34: =C34*E34 -> 84480 | G34: 12 nos × 8 blocks × 4 floors
B35: Subtotal — Upper Floor Slabs (×2 phases) | F35: =SUM(F29:F34) -> 6105160
A36: 3.2/2.3 | B36: Roof — Pitched & Flat (8 blocks)
B37: Pitched roof structure: steel purlins on RC beams | C37: 11856 | D37: m² | E37: 95 | F37: =C37*E37 -> 1126320 | G37: Roof plan area
B38: Flat roof structure to plant areas | C38: 2400 | D38: m² | E38: 165 | F38: =C38*E38 -> 396000 | G38: RC slab + screed to falls
B39: Zincalume metal sheet roofing 0.50mm | C39: 11856 | D39: m² | E39: 75 | F39: =C39*E39 -> 889200 | G39: Colour-coated, AZ150 coating
B40: PPGI flashings, ridge caps, eaves trims | C40: 2400 | D40: m | E40: 60 | F40: =C40*E40 -> 144000 | G40: Perimeter + ridges
B41: Aluminium box gutters 200×150mm | C41: 1920 | D41: m | E41: 110 | F41: =C41*E41 -> 211200 | G41: 240m per block × 8
...

Sheet FS
A1: DESIGN AND BUILD OF COASTAL DORMITORY EXPANSION CHANGI EAST DEVELOPMENT – TENDER REF: CE/25/T5/P/896
A4: FINAL SUMMARY FOR THE SCHEDULE OF WORKS | H4: SUBMISSION COST
A5: Section | B5: Description | D5: Page | E5: Phase A (S$) | F5: Phase B (S$) | H5: Phase A (S$) | I5: Phase B (S$)
A6: 1 | B6: Preliminaries and General | D6: SECT 1/53 | E6: =+'1_Prelim'!J536 -> 0 | F6: =+'1_Prelim'!N536 -> 0 | H6: 0 | I6: 0
A7: 2 | B7: Professional Fees | D7: SECT 2.SUM/1 | E7: ='2_Professional Fees'!K265 -> 0 | F7: ='2_Professional Fees'!N265 -> 0 | H7: ='2_Professional Fees'!R265 -> 0 | I7: =+'2_Professional Fees'!S92 -> 0
A8: 3 | B8: Building Works | D8: SECT 3.SUM/1 | E8: ='Sec 3 - Building Works'!O502 -> 0 | F8: ='Sec 3 - Building Works'!V502 -> 0 | H8: ='Sec 3 - Building Works'!Y502 -> 0 | I8: ='Sec 3 - Building Works'!Z502 -> 0
A9: 4 | B9: External Works | D9: SECT 4.SUM/1 | E9: =+'Sec 4 - External Works'!K68 -> 0 | F9: =+'Sec 4 - External Works'!N68 -> 0 | H9: =+'Sec 4 - External Works'!Q68 -> 0 | I9: =+'Sec 4 - External Works'!R68 -> 0
A10: 5 | B10: Mechanical & Electrical Works | D10: SECT 5.SUM/1 | H10: =+E10 -> 0 | I10: =+F10 -> 0
A12: ADD | B12: Insurance
A14: ADD | B14: Security Deposit
A16: TOTAL FOR WORKS CARRIED TO FORM OF TENDER (excluding GST) | E16: =SUM(E6:E15) -> 0 | F16: =SUM(F6:F15) -> 0 | H16: =SUM(H6:H15) -> 0 | I16: =SUM(I6:I15) -> 0

Sheet 1_Prelim
A1: DESIGN AND BUILD OF COASTAL DORMITORY EXPANSION FOR CHANGI EAST DEVELOPMENT
A2: REFERENCE NO.: CE/25/T5/P/896 SECTION 1 - PRELIMINARIES AND GENERAL
A3: CODE | B3: PAGE | C3: ITEM | D3: CLAUSE /REF | E3: DESCRIPTION | F3: UNIT | G3: U/RATE (S$) | H3: PHASE A (S$) | L3: PHASE B (S$)
H4: QTY | I4: AMOUNT (S$) | J4: AMT TO COLL (S$) | K4: REMARKS | L4: QTY | M4: AMOUNT (S$) | N4: AMT TO COLL (S$) | O4: REMARKS
A5: Prelim | B5: Sec1/1 | D5: A | E5: GENERAL MATTERS AND OBLIGATIONS | I5: =ROUND(H5*G5,2) -> 0 | J5: =ROUNDUP(I5,0) -> 0 | M5: =ROUND(L5*G5,2) -> 0 | N5: =ROUNDUP(M5,0) -> 0
A6: Prelim | B6: Sec1/1 | D6: 1 | E6: GENERAL | I6: =ROUND(H6*G6,2) -> 0 | J6: =ROUNDUP(I6,0) -> 0 | M6: =ROUND(L6*G6,2) -> 0 | N6: =ROUNDUP(M6,0) -> 0
A7: Prelim | B7: Sec1/1 | E7: The Preliminaries and General Section and the prices entered therein by the Contractor shall apply to the whole of the Works. | I7: =ROUND(H7*G7,2) -> 0 | J7: =ROUNDUP(I7,0) -> 0 | M7: =ROUND(L7*G7,2) -> 0 | N7: =ROUNDUP(M7,0) -> 0
A8: Prelim | B8: Sec1/1 | E8: The Contractor shall be deemed to have satisfied himself as to the sufficiency of his tender and of the prices in these Sections, all of which shall cover his obligations under the Contract and all work and expenditure necessary to carry out and bring the Works to completion. | I8: =ROUND(H8*G8,2) -> 0 | J8: =ROUNDUP(I8,0) -> 0 | M8: =ROUND(L8*G8,2) -> 0 | N8: =ROUNDUP(M8,0) -> 0
A9: Prelim | B9: Sec1/1 | E9: Without limitation to the Contractor's obligations under Clause 4.4 of the Conditions, any discrepancy brought forth after submission of the tender shall be interpreted at the sole discretion of the Superintending Officer whose decisions shall be final and binding and the Contractor shall deemed to have made all due allowances for the item or proposed work of better quality, greater quantity, or higher cost in the Contract Sum. | I9: =ROUND(H9*G9,2) -> 0 | J9: =ROUNDUP(I9,0) -> 0 | M9: =ROUND(L9*G9,2) -> 0 | N9: =ROUNDUP(M9,0) -> 0
A10: Prelim | B10: Sec1/1 | E10: Works not explicitly mentioned in the Contract Documents but are obviously necessary for the efficiency, stability and completion of the Works shall be included in the Contract Sum by the Contractor. | I10: =ROUND(H10*G10,2) -> 0 | J10: =ROUNDUP(I10,0) -> 0 | M10: =ROUND(L10*G10,2) -> 0 | N10: =ROUNDUP(M10,0) -> 0
A11: Prelim | B11: Sec1/1 | E11: Works mentioned in the Specifications but not shown in the Contract Drawings and vice versa will be nevertheless be deemed to be included in the Contract and shall be included in the Contract Sum. | I11: =ROUND(H11*G11,2) -> 0 | J11: =ROUNDUP(I11,0) -> 0 | M11: =ROUND(L11*G11,2) -> 0 | N11: =ROUNDUP(M11,0) -> 0
A12: Prelim | B12: Sec1/1 | D12: 2 | E12: ALTERATION TO TEXT | I12: =ROUND(H12*G12,2) -> 0 | J12: =ROUNDUP(I12,0) -> 0 | M12: =ROUND(L12*G12,2) -> 0 | N12: =ROUNDUP(M12,0) -> 0
A13: Prelim | B13: Sec1/1 | E13: The Tenderer shall study carefully the requirements of the Specifications, Conditions of Contract and all other parts of the Tender Documents and submit his Tender Offer only after he is satisfied with himself that he can meet all the requirements of this Invitation to Tender. | I13: =ROUND(H13*G13,2) -> 0 | J13: =ROUNDUP(I13,0) -> 0 | M13: =ROUND(L13*G13,2) -> 0 | N13: =ROUNDUP(M13,0) -> 0
A14: Prelim | B14: Sec1/1 | E14: No alterations or amendments shall be made to the Contract Documents unless authorised in writing by the Superintending Officer. The original text shall be adhered to if unauthorised alterations or amendments have been made by the Contractor. | I14: =ROUND(H14*G14,2) -> 0 | J14: =ROUNDUP(I14,0) -> 0 | M14: =ROUND(L14*G14,2) -> 0 | N14: =ROUNDUP(M14,0) -> 0
A15: Collection | B15: =+B14 -> Sec1/1 | E15: To Collection S$ | J15: =SUBTOTAL(9,J5:J14) -> 0 | N15: =SUBTOTAL(9,N5:N14) -> 0
A16: Prelim | B16: Sec1/2 | D16: A | E16: GENERAL MATTERS AND OBLIGATIONS (CONT'D) | I16: =ROUND(H16*G16,2) -> 0 | J16: =ROUNDUP(I16,0) -> 0 | M16: =ROUND(L16*G16,2) -> 0 | N16: =ROUNDUP(M16,0) -> 0
A17: Prelim | B17: Sec1/2 | D17: 3 | E17: CONDITIONS OF CONTRACT | I17: =ROUND(H17*G17,2) -> 0 | J17: =ROUNDUP(I17,0) -> 0 | M17: =ROUND(L17*G17,2) -> 0 | N17: =ROUNDUP(M17,0) -> 0
A18: Prelim | B18: Sec1/2 | E18: The Conditions of Contract to be used shall be the latest edition of the Public Sector Standard Conditions of Contract (PSSCOC) for Design and Build 2020 issued by the Building and Construction Authority (BCA), including List of Amendments, Appendix, any Option Modules and Particular Conditions of Contract and Particular Conditions of Contract for Contingency Works. | I18: =ROUND(H18*G18,2) -> 0 | J18: =ROUNDUP(I18,0) -> 0 | M18: =ROUND(L18*G18,2) -> 0 | N18: =ROUNDUP(M18,0) -> 0
A19: Prelim | B19: Sec1/2 | E19: The Contractor shall be bound by all the documents forming this Contract and he shall be deemed to have acquainted himself with all such documents before tendering as the Employer shall not entertain any claim for extra payment or time for the lack of knowledge. | I19: =ROUND(H19*G19,2) -> 0 | J19: =ROUNDUP(I19,0) -> 0 | M19: =ROUND(L19*G19,2) -> 0 | N19: =ROUNDUP(M19,0) -> 0
A20: Prelim | B20: Sec1/2 | D20: 4 | E20: FIRM PRICE CONTRACT | I20: =ROUND(H20*G20,2) -> 0 | J20: =ROUNDUP(I20,0) -> 0 | M20: =ROUND(L20*G20,2) -> 0 | N20: =ROUNDUP(M20,0) -> 0
A21: Prelim | B21: Sec1/2 | E21: This is a Lump Sum Contract without adjustments due to any fluctuations in the cost of labour, materials, plant, equipment, tools, transport, exchange rates and/or taxation. | I21: =ROUND(H21*G21,2) -> 0 | J21: =ROUNDUP(I21,0) -> 0 | M21: =ROUND(L21*G21,2) -> 0 | N21: =ROUNDUP(M21,0) -> 0
A22: Prelim | B22: Sec1/2 | E22: The Contract or the Contract Sum shall only be adjusted in accordance with the provisions of the Contract Documents. | I22: =ROUND(H22*G22,2) -> 0 | J22: =ROUNDUP(I22,0) -> 0 | M22: =ROUND(L22*G22,2) -> 0 | N22: =ROUNDUP(M22,0) -> 0
A23: Prelim | B23: Sec1/2 | E23: Any variations requring the omission of work, materials or goods shall be valued by measurement in accordance with Clause 20.1 of the Conditions of Contract, applying the relevant unit rates (or pro-rated unit rates, as the case may be) found in the Schedule of Works and/or Schedule of Rates. | I23: =ROUND(H23*G23,2) -> 0 | J23: =ROUNDUP(I23,0) -> 0 | M23: =ROUND(L23*G23,2) -> 0 | N23: =ROUNDUP(M23,0) -> 0
A24: Prelim | B24: Sec1/2 | E24: The Contractor shall provide everything necessary for the proper execution of the Works according to the true intent and meaning of the documents forming this Contract. Unless otherwise specifically stated, the following shall be deemed to be included in the Contract Sum: (a) Labour and all costs in connection therewith and any items of expenditure which are not allowed for elsewhere such as holidays with pay, Central Provident Fund contributions, Workers' Levy, Payroll Tax, travelling time and fares and any costs arising from recruiting foreign labourers, bonuses, preparatory and temporary work and all prefabrication work, and for delays due to exceptionally adverse weather conditions, and for working on shifts and/or overtime (if permitted by the SO); | I24: =ROUND(H24*G24,2) -> 0 | J24: =ROUNDUP(I24,0) -> 0 | M24: =ROUND(L24*G24,2) -> 0 | N24: =ROUNDUP(M24,0) -> 0
A25: Prelim | B25: Sec1/2 | E25: (b) Materials/goods/Plant and costs in connection therewith, including preparatory and temporary works and fittings and fixing goods/materials/Plant in position, wastage, fabrication costs, delivering, unloading, transferring, storing, returning packaging, handling, hoisting and lowering etc. inclusive of adequate protection; | I25: =ROUND(H25*G25,2) -> 0 | J25: =ROUNDUP(I25,0) -> 0 | M25: =ROUND(L25*G25,2) -> 0 | N25: =ROUNDUP(M25,0) -> 0
A26: Collection | B26: =+B25 -> Sec1/2 | E26: To Collection S$ | J26: =SUBTOTAL(9,J16:J25) -> 0 | N26: =SUBTOTAL(9,N16:N25) -> 0
A27: Prelim | B27: Sec1/3 | D27: A | E27: GENERAL MATTERS AND OBLIGATIONS (CONT'D) | I27: =ROUND(H27*G27,2) -> 0 | J27: =ROUNDUP(I27,0) -> 0 | M27: =ROUND(L27*G27,2) -> 0 | N27: =ROUNDUP(M27,0) -> 0
A28: Prelim | B28: Sec1/3 | D28: 4 | E28: FIRM PRICE CONTRACT (CONT'D) | I28: =ROUND(H28*G28,2) -> 0 | J28: =ROUNDUP(I28,0) -> 0 | M28: =ROUND(L28*G28,2) -> 0 | N28: =ROUNDUP(M28,0) -> 0
A29: Prelim | B29: Sec1/3 | E29: (c) Use of Construction Equipment, tools and vehicles, including maintenance and supply of fuel and other equipment necessary for the proper execution and completion of the Works, and all idle time, dismantling and removal of Construction Equipment, etc. off the site; | I29: =ROUND(H29*G29,2) -> 0 | J29: =ROUNDUP(I29,0) -> 0 | M29: =ROUND(L29*G29,2) -> 0 | N29: =ROUNDUP(M29,0) -> 0
A30: Prelim | B30: Sec1/3 | E30: (d) Complying with all the requirements of the Contract Documents, whether any requirement may or may not be particularly shown or described, provided that the same can be reasonably inferred therefrom, and any other obligations necessary for the proper execution, completion and maintenance of the Works. | I30: =ROUND(H30*G30,2) -> 0 | J30: =ROUNDUP(I30,0) -> 0 | M30: =ROUND(L30*G30,2) -> 0 | N30: =ROUNDUP(M30,0) -> 0
A31: Prelim | B31: Sec1/3 | E31: The onus of investigating and ascertaining the actual extent and nature of the Works contained in this Contract, prior to submission of the Tender, is solely with the Contractor. Any doubt as to the actual extent or nature of the Works should be clarified before the submission of Tender, as no subsequent claim arising out of lack of clarity or availability of information in respect of the Contract Documents shall be entertained. The Contractor shall be deemed to have made the necessary allowance for all and any contingency on account of this provision in the Contract Sum. | I31: =ROUND(H31*G31,2) -> 0 | J31: =ROUNDUP(I31,0) -> 0 | M31: =ROUND(L31*G31,2) -> 0 | N31: =ROUNDUP(M31,0) -> 0
A32: Prelim | B32: Sec1/3 | D32: 5 | E32: DISCREPANCIES IN DRAWINGS AND SPECIFICATIONS | I32: =ROUND(H32*G32,2) -> 0 | J32: =ROUNDUP(I32,0) -> 0 | M32: =ROUND(L32*G32,2) -> 0 | N32: =ROUNDUP(M32,0) -> 0
A33: Prelim | B33: Sec1/3 | E33: The Works shall be carried out in accordance with the Specifications and Drawings and such further instructions as may from time to time be issued by the SO. | I33: =ROUND(H33*G33,2) -> 0 | J33: =ROUNDUP(I33,0) -> 0 | M33: =ROUND(L33*G33,2) -> 0 | N33: =ROUNDUP(M33,0) -> 0
A34: Prelim | B34: Sec1/3 | E34: Where Works are not specified but shown on the Drawings, or can reasonably be inferred to be part of the Contract, and vice-versa, they shall be carried out as directed and to the entire satisfaction of the SO for the proper execution and completion of the Contract. The Contractor shall be deemed to have allowed for any additional costs and expenses incurred for complying with this provision. | I34: =ROUND(H34*G34,2) -> 0 | J34: =ROUNDUP(I34,0) -> 0 | M34: =ROUND(L34*G34,2) -> 0 | N34: =ROUNDUP(M34,0) -> 0
A35: Prelim | B35: Sec1/3 | E35: The Contractor shall check and verify all dimensions in the Drawings before commencement of Works. Engineering Drawings shall be verified against each other and against Architectural Drawings. | I35: =ROUND(H35*G35,2) -> 0 | J35: =ROUNDUP(I35,0) -> 0 | M35: =ROUND(L35*G35,2) -> 0 | N35: =ROUNDUP(M35,0) -> 0
A36: Prelim | B36: Sec1/3 | E36: In case of discrepancy between the figured dimensions and scaled dimensions, the figured dimensions shall prevail and the Contractor shall notify the SO in writing of such discrepancy. | I36: =ROUND(H36*G36,2) -> 0 | J36: =ROUNDUP(I36,0) -> 0 | M36: =ROUND(L36*G36,2) -> 0 | N36: =ROUNDUP(M36,0) -> 0
A37: Prelim | B37: Sec1/3 | E37: If the Works are completed without the discrepancies being brought to the attention of the SO for his decision, the Works shall then be deemed to be constructed in error by the Contractor who shall bear all costs of rectification. No claims for extension of time shall be entertained. | I37: =ROUND(H37*G37,2) -> 0 | J37: =ROUNDUP(I37,0) -> 0 | M37: =ROUND(L37*G37,2) -> 0 | N37: =ROUNDUP(M37,0) -> 0
A38: Collection | B38: =+B37 -> Sec1/3 | E38: To Collection S$ | J38: =SUBTOTAL(9,J27:J37) -> 0 | N38: =SUBTOTAL(9,N27:N37) -> 0
A39: Prelim | B39: Sec1/4 | D39: A | E39: GENERAL MATTERS AND OBLIGATIONS (CONT'D) | I39: =ROUND(H39*G39,2) -> 0 | J39: =ROUNDUP(I39,0) -> 0 | M39: =ROUND(L39*G39,2) -> 0 | N39: =ROUNDUP(M39,0) -> 0
A40: Prelim | B40: Sec1/4 | D40: 6 | E40: LABOUR, PLANT AND TOOLS | I40: =ROUND(H40*G40,2) -> 0 | J40: =ROUNDUP(I40,0) -> 0 | M40: =ROUND(L40*G40,2) -> 0 | N40: =ROUNDUP(M40,0) -> 0
...

Sheet 2_Professional Fees
A1: Tender No: CE/25/T5/P/896 | L1: Generally | R1: Markup
R2: A | S2: 0.2
A3: SECTION 2 | R3: B | S3: 0.1 | T3: PC rate
A4: DESIGN AND BUILD OF COASTAL DORMITORY EXPANSION FOR CHANGI EAST DEVELOPMENT | R4: C
A6: CODE | B6: PAGE | C6: ITEM | D6: DESCRIPTION | E6: UNIT | F6: Material (S$) | G6: Labour (S$) | H6: U/RATE (S$) | I6: Phase A Qty | J6: Phase A Sub-Total | K6: Phase A Amount (S$) | L6: Phase B Qty | M6: Phase B Sub-Total | N6: Phase B Amount (S$) | O6: REMARKS | Q6: MARKUP CODE | R6: SUBMISSION AMOUNT (S$) | S6: SUBMISSION AMOUNT (S$)
A7: Architect | B7: Sec 2.1/1 | D7: SECTION NO 2.1 - PROFESSIONAL FEES | H7: =+SUM(F7:G7) -> 0 | J7: =+ROUND(I7*H7,2) -> 0 | M7: =+ROUND(L7*H7,2) -> 0 | Q7: A | R7: =+ROUND((K7)*(1+SUMIF($R$2:$R$4,Q7,$S$2:$S$4)),0) -> 0 | S7: =+ROUND((N7)*(1+SUMIF($R$2:$R$4,Q7,$S$2:$S$4)),0) -> 0
A8: Architect | B8: =+B7 -> Sec 2.1/1 | H8: =+SUM(F8:G8) -> 0 | J8: =+ROUND(I8*H8,2) -> 0 | M8: =+ROUND(L8*H8,2) -> 0 | Q8: A | R8: =+ROUND((K8)*(1+SUMIF($R$2:$R$4,Q8,$S$2:$S$4)),0) -> 0 | S8: =+ROUND((N8)*(1+SUMIF($R$2:$R$4,Q8,$S$2:$S$4)),0) -> 0
A9: Architect | B9: =+B8 -> Sec 2.1/1 | C9: 1 | D9: ARCHITECT | H9: =+SUM(F9:G9) -> 0 | J9: =+ROUND(I9*H9,2) -> 0 | M9: =+ROUND(L9*H9,2) -> 0 | Q9: A | R9: =+ROUND((K9)*(1+SUMIF($R$2:$R$4,Q9,$S$2:$S$4)),0) -> 0 | S9: =+ROUND((N9)*(1+SUMIF($R$2:$R$4,Q9,$S$2:$S$4)),0) -> 0
A10: Architect | B10: =+B9 -> Sec 2.1/1 | H10: =+SUM(F10:G10) -> 0 | J10: =+ROUND(I10*H10,2) -> 0 | M10: =+ROUND(L10*H10,2) -> 0 | Q10: A | R10: =+ROUND((K10)*(1+SUMIF($R$2:$R$4,Q10,$S$2:$S$4)),0) -> 0 | S10: =+ROUND((N10)*(1+SUMIF($R$2:$R$4,Q10,$S$2:$S$4)),0) -> 0
A11: Architect | B11: =+B10 -> Sec 2.1/1 | C11: 1.1 | D11: Design Development Stage | H11: =+SUM(F11:G11) -> 0 | J11: =+ROUND(I11*H11,2) -> 0 | M11: =+ROUND(L11*H11,2) -> 0 | Q11: A | R11: =+ROUND((K11)*(1+SUMIF($R$2:$R$4,Q11,$S$2:$S$4)),0) -> 0 | S11: =+ROUND((N11)*(1+SUMIF($R$2:$R$4,Q11,$S$2:$S$4)),0) -> 0
A12: Architect | B12: =+B11 -> Sec 2.1/1 | H12: =+SUM(F12:G12) -> 0 | J12: =+ROUND(I12*H12,2) -> 0 | M12: =+ROUND(L12*H12,2) -> 0 | Q12: A | R12: =+ROUND((K12)*(1+SUMIF($R$2:$R$4,Q12,$S$2:$S$4)),0) -> 0 | S12: =+ROUND((N12)*(1+SUMIF($R$2:$R$4,Q12,$S$2:$S$4)),0) -> 0
A13: Architect | B13: =+B12 -> Sec 2.1/1 | C13: a | D13: Make submissions such as Development Control (DC) submission (where applicable) to relevant technical departments (for architectural works) for clearance | E13: 0.15 | G13: 0 | H13: =+SUM(F13:G13) -> 0 | J13: =+ROUND(I13*H13,2) -> 0 | K13: =SUM(J13:J13) -> 0 | M13: =+ROUND(L13*H13,2) -> 0 | N13: =SUM(M13:M13) -> 0 | Q13: A | R13: =+ROUND((K13)*(1+SUMIF($R$2:$R$4,Q13,$S$2:$S$4)),0) -> 0 | S13: =+ROUND((N13)*(1+SUMIF($R$2:$R$4,Q13,$S$2:$S$4)),0) -> 0
A14: Architect | B14: =+B13 -> Sec 2.1/1 | H14: =+SUM(F14:G14) -> 0 | J14: =+ROUND(I14*H14,2) -> 0 | M14: =+ROUND(L14*H14,2) -> 0 | Q14: A | R14: =+ROUND((K14)*(1+SUMIF($R$2:$R$4,Q14,$S$2:$S$4)),0) -> 0 | S14: =+ROUND((N14)*(1+SUMIF($R$2:$R$4,Q14,$S$2:$S$4)),0) -> 0
A15: Architect | B15: =+B14 -> Sec 2.1/1 | C15: b | D15: Obtain clearances (DC clearance) from relevant technical departments (for architectural works) | E15: 0.1 | G15: 0 | H15: =+SUM(F15:G15) -> 0 | J15: =+ROUND(I15*H15,2) -> 0 | K15: =SUM(J15:J15) -> 0 | M15: =+ROUND(L15*H15,2) -> 0 | N15: =SUM(M15:M15) -> 0 | Q15: A | R15: =+ROUND((K15)*(1+SUMIF($R$2:$R$4,Q15,$S$2:$S$4)),0) -> 0 | S15: =+ROUND((N15)*(1+SUMIF($R$2:$R$4,Q15,$S$2:$S$4)),0) -> 0
A16: Architect | B16: =+B15 -> Sec 2.1/1 | H16: =+SUM(F16:G16) -> 0 | J16: =+ROUND(I16*H16,2) -> 0 | M16: =+ROUND(L16*H16,2) -> 0 | Q16: A | R16: =+ROUND((K16)*(1+SUMIF($R$2:$R$4,Q16,$S$2:$S$4)),0) -> 0 | S16: =+ROUND((N16)*(1+SUMIF($R$2:$R$4,Q16,$S$2:$S$4)),0) -> 0
A17: Architect | B17: =+B16 -> Sec 2.1/1 | C17: c | D17: Obtain Building Plan approval from relevant technical departments (for architectural works) | E17: 0.05 | G17: 0 | H17: =+SUM(F17:G17) -> 0 | J17: =+ROUND(I17*H17,2) -> 0 | K17: =SUM(J17:J17) -> 0 | M17: =+ROUND(L17*H17,2) -> 0 | N17: =SUM(M17:M17) -> 0 | Q17: A | R17: =+ROUND((K17)*(1+SUMIF($R$2:$R$4,Q17,$S$2:$S$4)),0) -> 0 | S17: =+ROUND((N17)*(1+SUMIF($R$2:$R$4,Q17,$S$2:$S$4)),0) -> 0
A18: Architect | B18: =+B17 -> Sec 2.1/1 | H18: =+SUM(F18:G18) -> 0 | J18: =+ROUND(I18*H18,2) -> 0 | M18: =+ROUND(L18*H18,2) -> 0 | Q18: A | R18: =+ROUND((K18)*(1+SUMIF($R$2:$R$4,Q18,$S$2:$S$4)),0) -> 0 | S18: =+ROUND((N18)*(1+SUMIF($R$2:$R$4,Q18,$S$2:$S$4)),0) -> 0
A19: Architect | B19: =+B18 -> Sec 2.1/1 | C19: 1.2 | D19: Construction | H19: =+SUM(F19:G19) -> 0 | J19: =+ROUND(I19*H19,2) -> 0 | M19: =+ROUND(L19*H19,2) -> 0 | Q19: A | R19: =+ROUND((K19)*(1+SUMIF($R$2:$R$4,Q19,$S$2:$S$4)),0) -> 0 | S19: =+ROUND((N19)*(1+SUMIF($R$2:$R$4,Q19,$S$2:$S$4)),0) -> 0
A20: Architect | B20: =+B19 -> Sec 2.1/1 | H20: =+SUM(F20:G20) -> 0 | J20: =+ROUND(I20*H20,2) -> 0 | M20: =+ROUND(L20*H20,2) -> 0 | Q20: A | R20: =+ROUND((K20)*(1+SUMIF($R$2:$R$4,Q20,$S$2:$S$4)),0) -> 0 | S20: =+ROUND((N20)*(1+SUMIF($R$2:$R$4,Q20,$S$2:$S$4)),0) -> 0
A21: Architect | B21: =+B20 -> Sec 2.1/1 | C21: a | D21: During construction period in monthly instalments | E21: 0.5 | G21: 0 | H21: =+SUM(F21:G21) -> 0 | J21: =+ROUND(I21*H21,2) -> 0 | K21: =SUM(J21:J21) -> 0 | M21: =+ROUND(L21*H21,2) -> 0 | N21: =SUM(M21:M21) -> 0 | Q21: A | R21: =+ROUND((K21)*(1+SUMIF($R$2:$R$4,Q21,$S$2:$S$4)),0) -> 0 | S21: =+ROUND((N21)*(1+SUMIF($R$2:$R$4,Q21,$S$2:$S$4)),0) -> 0
A22: Architect | B22: =+B21 -> Sec 2.1/1 | H22: =+SUM(F22:G22) -> 0 | J22: =+ROUND(I22*H22,2) -> 0 | M22: =+ROUND(L22*H22,2) -> 0 | Q22: A | R22: =+ROUND((K22)*(1+SUMIF($R$2:$R$4,Q22,$S$2:$S$4)),0) -> 0 | S22: =+ROUND((N22)*(1+SUMIF($R$2:$R$4,Q22,$S$2:$S$4)),0) -> 0
A23: Architect | B23: =+B22 -> Sec 2.1/1 | C23: 1.3 | D23: Completion | H23: =+SUM(F23:G23) -> 0 | J23: =+ROUND(I23*H23,2) -> 0 | M23: =+ROUND(L23*H23,2) -> 0 | Q23: A | R23: =+ROUND((K23)*(1+SUMIF($R$2:$R$4,Q23,$S$2:$S$4)),0) -> 0 | S23: =+ROUND((N23)*(1+SUMIF($R$2:$R$4,Q23,$S$2:$S$4)),0) -> 0
A24: Architect | B24: =+B23 -> Sec 2.1/1 | H24: =+SUM(F24:G24) -> 0 | J24: =+ROUND(I24*H24,2) -> 0 | M24: =+ROUND(L24*H24,2) -> 0 | Q24: A | R24: =+ROUND((K24)*(1+SUMIF($R$2:$R$4,Q24,$S$2:$S$4)),0) -> 0 | S24: =+ROUND((N24)*(1+SUMIF($R$2:$R$4,Q24,$S$2:$S$4)),0) -> 0
A25: Architect | B25: =+B24 -> Sec 2.1/1 | C25: a | D25: Upon substantial completion and obtain Temporary Occupation Permit (TOP) | E25: 0.1 | G25: 0 | H25: =+SUM(F25:G25) -> 0 | J25: =+ROUND(I25*H25,2) -> 0 | K25: =SUM(J25:J25) -> 0 | M25: =+ROUND(L25*H25,2) -> 0 | N25: =SUM(M25:M25) -> 0 | Q25: A | R25: =+ROUND((K25)*(1+SUMIF($R$2:$R$4,Q25,$S$2:$S$4)),0) -> 0 | S25: =+ROUND((N25)*(1+SUMIF($R$2:$R$4,Q25,$S$2:$S$4)),0) -> 0
A26: Architect | B26: =+B25 -> Sec 2.1/1 | H26: =+SUM(F26:G26) -> 0 | J26: =+ROUND(I26*H26,2) -> 0 | M26: =+ROUND(L26*H26,2) -> 0 | Q26: A | R26: =+ROUND((K26)*(1+SUMIF($R$2:$R$4,Q26,$S$2:$S$4)),0) -> 0 | S26: =+ROUND((N26)*(1+SUMIF($R$2:$R$4,Q26,$S$2:$S$4)),0) -> 0
A27: Architect | B27: =+B26 -> Sec 2.1/1 | C27: b | D27: Verifying defects rectification and submission of documents (warranties, manuals, as-built drawings) | E27: 0.05 | G27: 0 | H27: =+SUM(F27:G27) -> 0 | J27: =+ROUND(I27*H27,2) -> 0 | K27: =SUM(J27:J27) -> 0 | M27: =+ROUND(L27*H27,2) -> 0 | N27: =SUM(M27:M27) -> 0 | Q27: A | R27: =+ROUND((K27)*(1+SUMIF($R$2:$R$4,Q27,$S$2:$S$4)),0) -> 0 | S27: =+ROUND((N27)*(1+SUMIF($R$2:$R$4,Q27,$S$2:$S$4)),0) -> 0
A28: Architect | B28: =+B27 -> Sec 2.1/1 | H28: =+SUM(F28:G28) -> 0 | J28: =+ROUND(I28*H28,2) -> 0 | M28: =+ROUND(L28*H28,2) -> 0 | Q28: A | R28: =+ROUND((K28)*(1+SUMIF($R$2:$R$4,Q28,$S$2:$S$4)),0) -> 0 | S28: =+ROUND((N28)*(1+SUMIF($R$2:$R$4,Q28,$S$2:$S$4)),0) -> 0
A29: Architect | B29: =+B28 -> Sec 2.1/1 | C29: c | D29: Obtain Certificate of Statutory Completion (CSC) /Final Completion Certificate (for non CSC projects)/ handing over completed works to relevant Authorities | E29: 0.05 | G29: 0 | H29: =+SUM(F29:G29) -> 0 | J29: =+ROUND(I29*H29,2) -> 0 | K29: =SUM(J29:J29) -> 0 | M29: =+ROUND(L29*H29,2) -> 0 | N29: =SUM(M29:M29) -> 0 | Q29: A | R29: =+ROUND((K29)*(1+SUMIF($R$2:$R$4,Q29,$S$2:$S$4)),0) -> 0 | S29: =+ROUND((N29)*(1+SUMIF($R$2:$R$4,Q29,$S$2:$S$4)),0) -> 0
A30: Architect | B30: =+B29 -> Sec 2.1/1 | H30: =+SUM(F30:G30) -> 0 | J30: =+ROUND(I30*H30,2) -> 0 | M30: =+ROUND(L30*H30,2) -> 0 | Q30: A | R30: =+ROUND((K30)*(1+SUMIF($R$2:$R$4,Q30,$S$2:$S$4)),0) -> 0 | S30: =+ROUND((N30)*(1+SUMIF($R$2:$R$4,Q30,$S$2:$S$4)),0) -> 0
A31: Collection | B31: =+B30 -> Sec 2.1/1 | D31: To Collection: | K31: =SUM(K8:K30) -> 0 | N31: =SUM(N7:N30) -> 0 | R31: =SUM(R7:R30) -> 0 | S31: =SUM(S7:S30) -> 0
A32: Structure | B32: Sec 2.1/2 | H32: =+SUM(F32:G32) -> 0 | J32: =+ROUND(I32*H32,2) -> 0 | M32: =+ROUND(L32*H32,2) -> 0 | Q32: A | R32: =+ROUND((K32)*(1+SUMIF($R$2:$R$4,Q32,$S$2:$S$4)),0) -> 0 | S32: =+ROUND((N32)*(1+SUMIF($R$2:$R$4,Q32,$S$2:$S$4)),0) -> 0
A33: Structure | B33: Sec 2.1/2 | C33: 2 | D33: CIVIL & STRUCTURAL ENGINEER | H33: =+SUM(F33:G33) -> 0 | J33: =+ROUND(I33*H33,2) -> 0 | M33: =+ROUND(L33*H33,2) -> 0 | Q33: A | R33: =+ROUND((K33)*(1+SUMIF($R$2:$R$4,Q33,$S$2:$S$4)),0) -> 0 | S33: =+ROUND((N33)*(1+SUMIF($R$2:$R$4,Q33,$S$2:$S$4)),0) -> 0
A34: Structure | B34: =+B33 -> Sec 2.1/2 | H34: =+SUM(F34:G34) -> 0 | J34: =+ROUND(I34*H34,2) -> 0 | M34: =+ROUND(L34*H34,2) -> 0 | Q34: A | R34: =+ROUND((K34)*(1+SUMIF($R$2:$R$4,Q34,$S$2:$S$4)),0) -> 0 | S34: =+ROUND((N34)*(1+SUMIF($R$2:$R$4,Q34,$S$2:$S$4)),0) -> 0
A35: Structure | B35: =+B34 -> Sec 2.1/2 | C35: 2.1 | D35: Design Development Stage | H35: =+SUM(F35:G35) -> 0 | J35: =+ROUND(I35*H35,2) -> 0 | M35: =+ROUND(L35*H35,2) -> 0 | Q35: A | R35: =+ROUND((K35)*(1+SUMIF($R$2:$R$4,Q35,$S$2:$S$4)),0) -> 0 | S35: =+ROUND((N35)*(1+SUMIF($R$2:$R$4,Q35,$S$2:$S$4)),0) -> 0
A36: Structure | B36: =+B35 -> Sec 2.1/2 | H36: =+SUM(F36:G36) -> 0 | J36: =+ROUND(I36*H36,2) -> 0 | M36: =+ROUND(L36*H36,2) -> 0 | Q36: A | R36: =+ROUND((K36)*(1+SUMIF($R$2:$R$4,Q36,$S$2:$S$4)),0) -> 0 | S36: =+ROUND((N36)*(1+SUMIF($R$2:$R$4,Q36,$S$2:$S$4)),0) -> 0
A37: Structure | B37: =+B36 -> Sec 2.1/2 | C37: a | D37: Make submission to relevant technical departments (for C&S works) for clearance — 10% | E37: 0.1 | G37: 0 | H37: =+SUM(F37:G37) -> 0 | J37: =+ROUND(I37*H37,2) -> 0 | K37: =SUM(J37:J37) -> 0 | M37: =+ROUND(L37*H37,2) -> 0 | N37: =SUM(M37:M37) -> 0 | Q37: A | R37: =+ROUND((K37)*(1+SUMIF($R$2:$R$4,Q37,$S$2:$S$4)),0) -> 0 | S37: =+ROUND((N37)*(1+SUMIF($R$2:$R$4,Q37,$S$2:$S$4)),0) -> 0
A38: Structure | B38: =+B37 -> Sec 2.1/2 | H38: =+SUM(F38:G38) -> 0 | J38: =+ROUND(I38*H38,2) -> 0 | M38: =+ROUND(L38*H38,2) -> 0 | Q38: A | R38: =+ROUND((K38)*(1+SUMIF($R$2:$R$4,Q38,$S$2:$S$4)),0) -> 0 | S38: =+ROUND((N38)*(1+SUMIF($R$2:$R$4,Q38,$S$2:$S$4)),0) -> 0
A39: Structure | B39: =+B38 -> Sec 2.1/2 | C39: b | D39: Obtain clearance from relevant technical departments (for C&S works) | E39: 0.05 | G39: 0 | H39: =+SUM(F39:G39) -> 0 | J39: =+ROUND(I39*H39,2) -> 0 | K39: =SUM(J39:J39) -> 0 | M39: =+ROUND(L39*H39,2) -> 0 | N39: =SUM(M39:M39) -> 0 | Q39: A | R39: =+ROUND((K39)*(1+SUMIF($R$2:$R$4,Q39,$S$2:$S$4)),0) -> 0 | S39: =+ROUND((N39)*(1+SUMIF($R$2:$R$4,Q39,$S$2:$S$4)),0) -> 0
A40: Structure | B40: =+B39 -> Sec 2.1/2 | H40: =+SUM(F40:G40) -> 0 | J40: =+ROUND(I40*H40,2) -> 0 | M40: =+ROUND(L40*H40,2) -> 0 | Q40: A | R40: =+ROUND((K40)*(1+SUMIF($R$2:$R$4,Q40,$S$2:$S$4)),0) -> 0 | S40: =+ROUND((N40)*(1+SUMIF($R$2:$R$4,Q40,$S$2:$S$4)),0) -> 0
A41: Structure | B41: =+B40 -> Sec 2.1/2 | C41: c | D41: Obtain Foundation Plan approval — 5% | E41: 0.05 | G41: 0 | H41: =+SUM(F41:G41) -> 0 | J41: =+ROUND(I41*H41,2) -> 0 | K41: =SUM(J41:J41) -> 0 | M41: =+ROUND(L41*H41,2) -> 0 | N41: =SUM(M41:M41) -> 0 | Q41: A | R41: =+ROUND((K41)*(1+SUMIF($R$2:$R$4,Q41,$S$2:$S$4)),0) -> 0 | S41: =+ROUND((N41)*(1+SUMIF($R$2:$R$4,Q41,$S$2:$S$4)),0) -> 0
...

Sheet Sec 3 - Building Works
A1: Tender No: CE/25/T5/P/896 | Y1: Markup
Y2: A | Z2: 0.2
A3: SECTION 3 | Y3: B | Z3: 0.1 | AA3: PC rate
A4: DESIGN AND BUILD OF COASTAL DORMITORY EXPANSION FOR CHANGI EAST DEVELOPMENT | Y4: C
I5: Type 1 - | J5: 4 | K5: Type 3 - | L5: 2 | P5: Type 1 - | Q5: 2 | R5: Type 3 - | S5: 3
A6: CODE | B6: PAGE | C6: ITEM | D6: DESCRIPTION | E6: UNIT | F6: Material (S$) | G6: Labour (S$) | H6: U/RATE (S$) | I6: Qty per Block | J6: Type 1 Qty | K6: Qty per Block | L6: Type 3 Qty | M6: Phase A Qty | N6: Phase A Sub-Total | O6: Phase A Amount (S$) | P6: Qty per Block | Q6: Type 1 Qty | R6: Qty per Block | S6: Type 3 Qty | T6: Phase B Qty | U6: Phase B Sub-Total | V6: Phase B Amount (S$) | W6: REMARKS | X6: MARKUP CODE | Y6: Phase A SUBMISSION AMOUNT (S$) | Z6: Phase B SUBMISSION AMOUNT (S$)
A7: WP | B7: 3.2/1 | D7: SECTION NO 3.2 — DORMITORY BLOCKS | H7: =+SUM(F7:G7) -> 0 | J7: =+I7*$J$5 -> 0 | L7: =+K7*$L$5 -> 0 | M7: =+J7+L7 -> 0 | N7: =+ROUND(M7*H7,2) -> 0 | Q7: =+P7*$Q$5 -> 0 | S7: =+R7*$S$5 -> 0 | T7: =+Q7+S7 -> 0 | U7: =+ROUND(T7*H7,2) -> 0 | X7: A | Y7: =+ROUND((O7)*(1+SUMIF($Y$2:$Y$4,X7,$Z$2:$Z$4)),0) -> 0 | Z7: =+ROUND((V7)*(1+SUMIF($Y$2:$Y$4,X7,$Z$2:$Z$4)),0) -> 0
A8: WP | B8: =+B7 -> 3.2/1 | D8: Detailed Design, Construct, Supply, Install, Complete, Testing and Commissioning of Workers Dormitory Blocks and Associated Facilities | H8: =+SUM(F8:G8) -> 0 | J8: =+I8*$J$5 -> 0 | L8: =+K8*$L$5 -> 0 | M8: =+J8+L8 -> 0 | N8: =+ROUND(M8*H8,2) -> 0 | Q8: =+P8*$Q$5 -> 0 | S8: =+R8*$S$5 -> 0 | T8: =+Q8+S8 -> 0 | U8: =+ROUND(T8*H8,2) -> 0 | X8: A | Y8: =+ROUND((O8)*(1+SUMIF($Y$2:$Y$4,X8,$Z$2:$Z$4)),0) -> 0 | Z8: =+ROUND((V8)*(1+SUMIF($Y$2:$Y$4,X8,$Z$2:$Z$4)),0) -> 0
A9: WP | B9: =+B8 -> 3.2/1 | C9: 1 | D9: SUBSTRUCTURE | H9: =+SUM(F9:G9) -> 0 | J9: =+I9*$J$5 -> 0 | L9: =+K9*$L$5 -> 0 | M9: =+J9+L9 -> 0 | N9: =+ROUND(M9*H9,2) -> 0 | Q9: =+P9*$Q$5 -> 0 | S9: =+R9*$S$5 -> 0 | T9: =+Q9+S9 -> 0 | U9: =+ROUND(T9*H9,2) -> 0 | X9: A | Y9: =+ROUND((O9)*(1+SUMIF($Y$2:$Y$4,X9,$Z$2:$Z$4)),0) -> 0 | Z9: =+ROUND((V9)*(1+SUMIF($Y$2:$Y$4,X9,$Z$2:$Z$4)),0) -> 0
A10: WP | B10: =+B9 -> 3.2/1 | C10: 1.1 | D10: EarthWorks | H10: =+SUM(F10:G10) -> 0 | J10: =+I10*$J$5 -> 0 | L10: =+K10*$L$5 -> 0 | M10: =+J10+L10 -> 0 | N10: =+ROUND(M10*H10,2) -> 0 | Q10: =+P10*$Q$5 -> 0 | S10: =+R10*$S$5 -> 0 | T10: =+Q10+S10 -> 0 | U10: =+ROUND(T10*H10,2) -> 0 | X10: A | Y10: =+ROUND((O10)*(1+SUMIF($Y$2:$Y$4,X10,$Z$2:$Z$4)),0) -> 0 | Z10: =+ROUND((V10)*(1+SUMIF($Y$2:$Y$4,X10,$Z$2:$Z$4)),0) -> 0
A11: WP | B11: =+B10 -> 3.2/1 | C11: 1.1.1 | D11: Bituminous waterproof membrane | E11: m2 | H11: =+SUM(F11:G11) -> 0 | J11: =+I11*$J$5 -> 0 | L11: =+K11*$L$5 -> 0 | M11: =+J11+L11 -> 0 | N11: =+ROUND(M11*H11,2) -> 0 | O11: =N11 -> 0 | Q11: =+P11*$Q$5 -> 0 | S11: =+R11*$S$5 -> 0 | T11: =+Q11+S11 -> 0 | U11: =+ROUND(T11*H11,2) -> 0 | V11: =U11 -> 0 | X11: A | Y11: =+ROUND((O11)*(1+SUMIF($Y$2:$Y$4,X11,$Z$2:$Z$4)),0) -> 0 | Z11: =+ROUND((V11)*(1+SUMIF($Y$2:$Y$4,X11,$Z$2:$Z$4)),0) -> 0
A12: Termite | B12: =+B11 -> 3.2/1 | C12: 1.1.2 | D12: Anti-termite treatment | E12: LS | H12: =+SUM(F12:G12) -> 0 | J12: =+I12*$J$5 -> 0 | L12: =+K12*$L$5 -> 0 | M12: =+J12+L12 -> 0 | N12: =+ROUND(M12*H12,2) -> 0 | O12: =N12 -> 0 | Q12: =+P12*$Q$5 -> 0 | S12: =+R12*$S$5 -> 0 | T12: =+Q12+S12 -> 0 | U12: =+ROUND(T12*H12,2) -> 0 | V12: =U12 -> 0 | X12: A | Y12: =+ROUND((O12)*(1+SUMIF($Y$2:$Y$4,X12,$Z$2:$Z$4)),0) -> 0 | Z12: =+ROUND((V12)*(1+SUMIF($Y$2:$Y$4,X12,$Z$2:$Z$4)),0) -> 0
A13: Earth | B13: =+B12 -> 3.2/1 | C13: 1.1.3 | D13: Excavation, Backfill and Disposal | H13: =+SUM(F13:G13) -> 0 | J13: =+I13*$J$5 -> 0 | L13: =+K13*$L$5 -> 0 | M13: =+J13+L13 -> 0 | N13: =+ROUND(M13*H13,2) -> 0 | O13: =N13 -> 0 | Q13: =+P13*$Q$5 -> 0 | S13: =+R13*$S$5 -> 0 | T13: =+Q13+S13 -> 0 | U13: =+ROUND(T13*H13,2) -> 0 | V13: =U13 -> 0 | X13: A | Y13: =+ROUND((O13)*(1+SUMIF($Y$2:$Y$4,X13,$Z$2:$Z$4)),0) -> 0 | Z13: =+ROUND((V13)*(1+SUMIF($Y$2:$Y$4,X13,$Z$2:$Z$4)),0) -> 0
A14: Earth | B14: =+B13 -> 3.2/1 | D14: Excavation | E14: m3 | H14: =+SUM(F14:G14) -> 0 | J14: =+I14*$J$5 -> 0 | L14: =+K14*$L$5 -> 0 | M14: =+J14+L14 -> 0 | N14: =+ROUND(M14*H14,2) -> 0 | O14: =N14 -> 0 | Q14: =+P14*$Q$5 -> 0 | S14: =+R14*$S$5 -> 0 | T14: =+Q14+S14 -> 0 | U14: =+ROUND(T14*H14,2) -> 0 | V14: =U14 -> 0 | X14: A | Y14: =+ROUND((O14)*(1+SUMIF($Y$2:$Y$4,X14,$Z$2:$Z$4)),0) -> 0 | Z14: =+ROUND((V14)*(1+SUMIF($Y$2:$Y$4,X14,$Z$2:$Z$4)),0) -> 0
A15: Earth | B15: =+B14 -> 3.2/1 | D15: Backfill | E15: m3 | H15: =+SUM(F15:G15) -> 0 | J15: =+I15*$J$5 -> 0 | L15: =+K15*$L$5 -> 0 | M15: =+J15+L15 -> 0 | N15: =+ROUND(M15*H15,2) -> 0 | O15: =N15 -> 0 | Q15: =+P15*$Q$5 -> 0 | S15: =+R15*$S$5 -> 0 | T15: =+Q15+S15 -> 0 | U15: =+ROUND(T15*H15,2) -> 0 | V15: =U15 -> 0 | X15: A | Y15: =+ROUND((O15)*(1+SUMIF($Y$2:$Y$4,X15,$Z$2:$Z$4)),0) -> 0 | Z15: =+ROUND((V15)*(1+SUMIF($Y$2:$Y$4,X15,$Z$2:$Z$4)),0) -> 0
A16: Earth | B16: =+B15 -> 3.2/1 | D16: Disposal | E16: m3 | H16: =+SUM(F16:G16) -> 0 | J16: =+I16*$J$5 -> 0 | L16: =+K16*$L$5 -> 0 | M16: =+J16+L16 -> 0 | N16: =+ROUND(M16*H16,2) -> 0 | O16: =N16 -> 0 | Q16: =+P16*$Q$5 -> 0 | S16: =+R16*$S$5 -> 0 | T16: =+Q16+S16 -> 0 | U16: =+ROUND(T16*H16,2) -> 0 | V16: =U16 -> 0 | X16: A | Y16: =+ROUND((O16)*(1+SUMIF($Y$2:$Y$4,X16,$Z$2:$Z$4)),0) -> 0 | Z16: =+ROUND((V16)*(1+SUMIF($Y$2:$Y$4,X16,$Z$2:$Z$4)),0) -> 0
A17: SubLean | B17: =+B13 -> 3.2/1 | C17: 1.2 | D17: Raft Foundation | H17: =+SUM(F17:G17) -> 0 | J17: =+I17*$J$5 -> 0 | L17: =+K17*$L$5 -> 0 | M17: =+J17+L17 -> 0 | N17: =+ROUND(M17*H17,2) -> 0 | Q17: =+P17*$Q$5 -> 0 | S17: =+R17*$S$5 -> 0 | T17: =+Q17+S17 -> 0 | U17: =+ROUND(T17*H17,2) -> 0 | X17: A | Y17: =+ROUND((O17)*(1+SUMIF($Y$2:$Y$4,X17,$Z$2:$Z$4)),0) -> 0 | Z17: =+ROUND((V17)*(1+SUMIF($Y$2:$Y$4,X17,$Z$2:$Z$4)),0) -> 0
A18: SubLean | B18: =+B17 -> 3.2/1 | C18: 1.2.1 | D18: Lean concrete | E18: m2 | H18: =+SUM(F18:G18) -> 0 | J18: =+I18*$J$5 -> 0 | L18: =+K18*$L$5 -> 0 | M18: =+J18+L18 -> 0 | N18: =+ROUND(M18*H18,2) -> 0 | O18: =N18 -> 0 | Q18: =+P18*$Q$5 -> 0 | S18: =+R18*$S$5 -> 0 | T18: =+Q18+S18 -> 0 | U18: =+ROUND(T18*H18,2) -> 0 | V18: =U18 -> 0 | X18: A | Y18: =+ROUND((O18)*(1+SUMIF($Y$2:$Y$4,X18,$Z$2:$Z$4)),0) -> 0 | Z18: =+ROUND((V18)*(1+SUMIF($Y$2:$Y$4,X18,$Z$2:$Z$4)),0) -> 0
A19: SubLean | B19: =+B18 -> 3.2/1 | C19: 1.2.2 | D19: Hardcore | E19: m2 | H19: =+SUM(F19:G19) -> 0 | J19: =+I19*$J$5 -> 0 | L19: =+K19*$L$5 -> 0 | M19: =+J19+L19 -> 0 | N19: =+ROUND(M19*H19,2) -> 0 | O19: =N19 -> 0 | Q19: =+P19*$Q$5 -> 0 | S19: =+R19*$S$5 -> 0 | T19: =+Q19+S19 -> 0 | U19: =+ROUND(T19*H19,2) -> 0 | V19: =U19 -> 0 | X19: A | Y19: =+ROUND((O19)*(1+SUMIF($Y$2:$Y$4,X19,$Z$2:$Z$4)),0) -> 0 | Z19: =+ROUND((V19)*(1+SUMIF($Y$2:$Y$4,X19,$Z$2:$Z$4)),0) -> 0
A20: SubConc(H) | B20: =+B19 -> 3.2/1 | C20: 1.2.3 | D20: Concrete | E20: m3 | H20: =+SUM(F20:G20) -> 0 | J20: =+I20*$J$5 -> 0 | L20: =+K20*$L$5 -> 0 | M20: =+J20+L20 -> 0 | N20: =+ROUND(M20*H20,2) -> 0 | O20: =N20 -> 0 | Q20: =+P20*$Q$5 -> 0 | S20: =+R20*$S$5 -> 0 | T20: =+Q20+S20 -> 0 | U20: =+ROUND(T20*H20,2) -> 0 | V20: =U20 -> 0 | X20: A | Y20: =+ROUND((O20)*(1+SUMIF($Y$2:$Y$4,X20,$Z$2:$Z$4)),0) -> 0 | Z20: =+ROUND((V20)*(1+SUMIF($Y$2:$Y$4,X20,$Z$2:$Z$4)),0) -> 0
A21: SubFW(H) | B21: =+B20 -> 3.2/1 | C21: 1.2.4 | D21: Formwork | E21: m2 | H21: =+SUM(F21:G21) -> 0 | J21: =+I21*$J$5 -> 0 | L21: =+K21*$L$5 -> 0 | M21: =+J21+L21 -> 0 | N21: =+ROUND(M21*H21,2) -> 0 | O21: =N21 -> 0 | Q21: =+P21*$Q$5 -> 0 | S21: =+R21*$S$5 -> 0 | T21: =+Q21+S21 -> 0 | U21: =+ROUND(T21*H21,2) -> 0 | V21: =U21 -> 0 | X21: A | Y21: =+ROUND((O21)*(1+SUMIF($Y$2:$Y$4,X21,$Z$2:$Z$4)),0) -> 0 | Z21: =+ROUND((V21)*(1+SUMIF($Y$2:$Y$4,X21,$Z$2:$Z$4)),0) -> 0
A22: SubBar(H) | B22: =+B21 -> 3.2/1 | C22: 1.2.5 | D22: Reinforcement | H22: =+SUM(F22:G22) -> 0 | J22: =+I22*$J$5 -> 0 | L22: =+K22*$L$5 -> 0 | M22: =+J22+L22 -> 0 | N22: =+ROUND(M22*H22,2) -> 0 | O22: =N22 -> 0 | Q22: =+P22*$Q$5 -> 0 | S22: =+R22*$S$5 -> 0 | T22: =+Q22+S22 -> 0 | U22: =+ROUND(T22*H22,2) -> 0 | V22: =U22 -> 0 | X22: A | Y22: =+ROUND((O22)*(1+SUMIF($Y$2:$Y$4,X22,$Z$2:$Z$4)),0) -> 0 | Z22: =+ROUND((V22)*(1+SUMIF($Y$2:$Y$4,X22,$Z$2:$Z$4)),0) -> 0
A23: Other | B23: =+B22 -> 3.2/1 | C23: 1.3 | D23: Plate Load Test | E23: no | H23: =+SUM(F23:G23) -> 0 | J23: =+I23*$J$5 -> 0 | L23: =+K23*$L$5 -> 0 | M23: =+J23+L23 -> 0 | N23: =+ROUND(M23*H23,2) -> 0 | O23: =N23 -> 0 | Q23: =+P23*$Q$5 -> 0 | S23: =+R23*$S$5 -> 0 | T23: =+Q23+S23 -> 0 | U23: =+ROUND(T23*H23,2) -> 0 | V23: =U23 -> 0 | X23: A | Y23: =+ROUND((O23)*(1+SUMIF($Y$2:$Y$4,X23,$Z$2:$Z$4)),0) -> 0 | Z23: =+ROUND((V23)*(1+SUMIF($Y$2:$Y$4,X23,$Z$2:$Z$4)),0) -> 0
A24: Collection | B24: =+B23 -> 3.2/1 | D24: To Collection: | J24: =+I24*$J$5 -> 0 | L24: =+K24*$L$5 -> 0 | M24: =+J24+L24 -> 0 | N24: =SUM(N7:N23) -> 0 | O24: =SUM(O7:O23) -> 0 | Q24: =+P24*$Q$5 -> 0 | S24: =+R24*$S$5 -> 0 | T24: =+Q24+S24 -> 0 | U24: =SUM(U7:U23) -> 0 | V24: =SUM(V7:V23) -> 0 | X24: A | Y24: =SUM(Y7:Y23) -> 0 | Z24: =SUM(Z7:Z23) -> 0
A25: Steel | B25: 3.2/2 | C25: 2 | D25: SUPERSTRUCTURE | H25: =+SUM(F25:G25) -> 0 | J25: =+I25*$J$5 -> 0 | L25: =+K25*$L$5 -> 0 | M25: =+J25+L25 -> 0 | N25: =+ROUND(M25*H25,2) -> 0 | Q25: =+P25*$Q$5 -> 0 | S25: =+R25*$S$5 -> 0 | T25: =+Q25+S25 -> 0 | U25: =+ROUND(T25*H25,2) -> 0 | X25: A | Y25: =+ROUND((O25)*(1+SUMIF($Y$2:$Y$4,X25,$Z$2:$Z$4)),0) -> 0 | Z25: =+ROUND((V25)*(1+SUMIF($Y$2:$Y$4,X25,$Z$2:$Z$4)),0) -> 0
A26: Steel | B26: =+B25 -> 3.2/2 | C26: 2.1 | D26: Frame | H26: =+SUM(F26:G26) -> 0 | J26: =+I26*$J$5 -> 0 | L26: =+K26*$L$5 -> 0 | M26: =+J26+L26 -> 0 | N26: =+ROUND(M26*H26,2) -> 0 | O26: =N26 -> 0 | Q26: =+P26*$Q$5 -> 0 | S26: =+R26*$S$5 -> 0 | T26: =+Q26+S26 -> 0 | U26: =+ROUND(T26*H26,2) -> 0 | V26: =U26 -> 0 | X26: A | Y26: =+ROUND((O26)*(1+SUMIF($Y$2:$Y$4,X26,$Z$2:$Z$4)),0) -> 0 | Z26: =+ROUND((V26)*(1+SUMIF($Y$2:$Y$4,X26,$Z$2:$Z$4)),0) -> 0
A27: Steel | B27: =+B26 -> 3.2/2 | C27: 2.1.1 | D27: Structural Frame including Beam, Column, Trusses and necessary finishes and coating | H27: =+SUM(F27:G27) -> 0 | J27: =+I27*$J$5 -> 0 | L27: =+K27*$L$5 -> 0 | M27: =+J27+L27 -> 0 | N27: =+ROUND(M27*H27,2) -> 0 | O27: =N27 -> 0 | Q27: =+P27*$Q$5 -> 0 | S27: =+R27*$S$5 -> 0 | T27: =+Q27+S27 -> 0 | U27: =+ROUND(T27*H27,2) -> 0 | V27: =U27 -> 0 | X27: A | Y27: =+ROUND((O27)*(1+SUMIF($Y$2:$Y$4,X27,$Z$2:$Z$4)),0) -> 0 | Z27: =+ROUND((V27)*(1+SUMIF($Y$2:$Y$4,X27,$Z$2:$Z$4)),0) -> 0
A28: SuperConc(H) | B28: =+B25 -> 3.2/2 | C28: 2.2 | D28: Upper floors | H28: =+SUM(F28:G28) -> 0 | J28: =+I28*$J$5 -> 0 | L28: =+K28*$L$5 -> 0 | M28: =+J28+L28 -> 0 | N28: =+ROUND(M28*H28,2) -> 0 | O28: =N28 -> 0 | Q28: =+P28*$Q$5 -> 0 | S28: =+R28*$S$5 -> 0 | T28: =+Q28+S28 -> 0 | U28: =+ROUND(T28*H28,2) -> 0 | V28: =U28 -> 0 | X28: A | Y28: =+ROUND((O28)*(1+SUMIF($Y$2:$Y$4,X28,$Z$2:$Z$4)),0) -> 0 | Z28: =+ROUND((V28)*(1+SUMIF($Y$2:$Y$4,X28,$Z$2:$Z$4)),0) -> 0
A29: SuperConc(H) | B29: =+B26 -> 3.2/2 | C29: 2.2.1 | D29: Upper Floor Slabs — Contractor Proposed System (Tenderer to insert the proposed system) | H29: =+SUM(F29:G29) -> 0 | J29: =+I29*$J$5 -> 0 | L29: =+K29*$L$5 -> 0 | M29: =+J29+L29 -> 0 | N29: =+ROUND(M29*H29,2) -> 0 | O29: =N29 -> 0 | Q29: =+P29*$Q$5 -> 0 | S29: =+R29*$S$5 -> 0 | T29: =+Q29+S29 -> 0 | U29: =+ROUND(T29*H29,2) -> 0 | V29: =U29 -> 0 | X29: A | Y29: =+ROUND((O29)*(1+SUMIF($Y$2:$Y$4,X29,$Z$2:$Z$4)),0) -> 0 | Z29: =+ROUND((V29)*(1+SUMIF($Y$2:$Y$4,X29,$Z$2:$Z$4)),0) -> 0
A30: SubConc(H) | B30: =+B29 -> 3.2/2 | D30: Concrete | E30: m3 | H30: =+SUM(F30:G30) -> 0 | J30: =+I30*$J$5 -> 0 | L30: =+K30*$L$5 -> 0 | M30: =+J30+L30 -> 0 | N30: =+ROUND(M30*H30,2) -> 0 | O30: =N30 -> 0 | Q30: =+P30*$Q$5 -> 0 | S30: =+R30*$S$5 -> 0 | T30: =+Q30+S30 -> 0 | U30: =+ROUND(T30*H30,2) -> 0 | V30: =U30 -> 0 | X30: A | Y30: =+ROUND((O30)*(1+SUMIF($Y$2:$Y$4,X30,$Z$2:$Z$4)),0) -> 0 | Z30: =+ROUND((V30)*(1+SUMIF($Y$2:$Y$4,X30,$Z$2:$Z$4)),0) -> 0
A31: SubFW(H) | B31: =+B30 -> 3.2/2 | D31: Formwork | E31: m2 | H31: =+SUM(F31:G31) -> 0 | J31: =+I31*$J$5 -> 0 | L31: =+K31*$L$5 -> 0 | M31: =+J31+L31 -> 0 | N31: =+ROUND(M31*H31,2) -> 0 | O31: =N31 -> 0 | Q31: =+P31*$Q$5 -> 0 | S31: =+R31*$S$5 -> 0 | T31: =+Q31+S31 -> 0 | U31: =+ROUND(T31*H31,2) -> 0 | V31: =U31 -> 0 | X31: A | Y31: =+ROUND((O31)*(1+SUMIF($Y$2:$Y$4,X31,$Z$2:$Z$4)),0) -> 0 | Z31: =+ROUND((V31)*(1+SUMIF($Y$2:$Y$4,X31,$Z$2:$Z$4)),0) -> 0
A32: SubBar(H) | B32: =+B31 -> 3.2/2 | D32: Reinforcement | H32: =+SUM(F32:G32) -> 0 | J32: =+I32*$J$5 -> 0 | L32: =+K32*$L$5 -> 0 | M32: =+J32+L32 -> 0 | N32: =+ROUND(M32*H32,2) -> 0 | O32: =N32 -> 0 | Q32: =+P32*$Q$5 -> 0 | S32: =+R32*$S$5 -> 0 | T32: =+Q32+S32 -> 0 | U32: =+ROUND(T32*H32,2) -> 0 | V32: =U32 -> 0 | X32: A | Y32: =+ROUND((O32)*(1+SUMIF($Y$2:$Y$4,X32,$Z$2:$Z$4)),0) -> 0 | Z32: =+ROUND((V32)*(1+SUMIF($Y$2:$Y$4,X32,$Z$2:$Z$4)),0) -> 0
A33: RWDP | B33: =+B28 -> 3.2/2 | C33: 2.2.2 | D33: Drainage to Corridor | H33: =+SUM(F33:G33) -> 0 | J33: =+I33*$J$5 -> 0 | L33: =+K33*$L$5 -> 0 | M33: =+J33+L33 -> 0 | N33: =+ROUND(M33*H33,2) -> 0 | O33: =N33 -> 0 | Q33: =+P33*$Q$5 -> 0 | S33: =+R33*$S$5 -> 0 | T33: =+Q33+S33 -> 0 | U33: =+ROUND(T33*H33,2) -> 0 | V33: =U33 -> 0 | X33: A | Y33: =+ROUND((O33)*(1+SUMIF($Y$2:$Y$4,X33,$Z$2:$Z$4)),0) -> 0 | Z33: =+ROUND((V33)*(1+SUMIF($Y$2:$Y$4,X33,$Z$2:$Z$4)),0) -> 0
A34: RWDP | B34: =+B29 -> 3.2/2 | C34: 2.2.2.1 | D34: Rainwater pipes | E34: m | H34: =+SUM(F34:G34) -> 0 | J34: =+I34*$J$5 -> 0 | L34: =+K34*$L$5 -> 0 | M34: =+J34+L34 -> 0 | N34: =+ROUND(M34*H34,2) -> 0 | O34: =N34 -> 0 | Q34: =+P34*$Q$5 -> 0 | S34: =+R34*$S$5 -> 0 | T34: =+Q34+S34 -> 0 | U34: =+ROUND(T34*H34,2) -> 0 | V34: =U34 -> 0 | X34: A | Y34: =+ROUND((O34)*(1+SUMIF($Y$2:$Y$4,X34,$Z$2:$Z$4)),0) -> 0 | Z34: =+ROUND((V34)*(1+SUMIF($Y$2:$Y$4,X34,$Z$2:$Z$4)),0) -> 0
A35: RWDP | B35: =+B34 -> 3.2/2 | C35: 2.2.2.2 | D35: Floor outlets | E35: no | H35: =+SUM(F35:G35) -> 0 | J35: =+I35*$J$5 -> 0 | L35: =+K35*$L$5 -> 0 | M35: =+J35+L35 -> 0 | N35: =+ROUND(M35*H35,2) -> 0 | O35: =N35 -> 0 | Q35: =+P35*$Q$5 -> 0 | S35: =+R35*$S$5 -> 0 | T35: =+Q35+S35 -> 0 | U35: =+ROUND(T35*H35,2) -> 0 | V35: =U35 -> 0 | X35: A | Y35: =+ROUND((O35)*(1+SUMIF($Y$2:$Y$4,X35,$Z$2:$Z$4)),0) -> 0 | Z35: =+ROUND((V35)*(1+SUMIF($Y$2:$Y$4,X35,$Z$2:$Z$4)),0) -> 0
A36: RoofStruc | B36: =+B33 -> 3.2/2 | C36: 2.3 | D36: Roof | H36: =+SUM(F36:G36) -> 0 | J36: =+I36*$J$5 -> 0 | L36: =+K36*$L$5 -> 0 | M36: =+J36+L36 -> 0 | N36: =+ROUND(M36*H36,2) -> 0 | O36: =N36 -> 0 | Q36: =+P36*$Q$5 -> 0 | S36: =+R36*$S$5 -> 0 | T36: =+Q36+S36 -> 0 | U36: =+ROUND(T36*H36,2) -> 0 | V36: =U36 -> 0 | X36: A | Y36: =+ROUND((O36)*(1+SUMIF($Y$2:$Y$4,X36,$Z$2:$Z$4)),0) -> 0 | Z36: =+ROUND((V36)*(1+SUMIF($Y$2:$Y$4,X36,$Z$2:$Z$4)),0) -> 0
A37: RoofStruc | B37: =+B34 -> 3.2/2 | C37: 2.3.1 | D37: Roof Structure | H37: =+SUM(F37:G37) -> 0 | J37: =+I37*$J$5 -> 0 | L37: =+K37*$L$5 -> 0 | M37: =+J37+L37 -> 0 | N37: =+ROUND(M37*H37,2) -> 0 | O37: =N37 -> 0 | Q37: =+P37*$Q$5 -> 0 | S37: =+R37*$S$5 -> 0 | T37: =+Q37+S37 -> 0 | U37: =+ROUND(T37*H37,2) -> 0 | V37: =U37 -> 0 | X37: A | Y37: =+ROUND((O37)*(1+SUMIF($Y$2:$Y$4,X37,$Z$2:$Z$4)),0) -> 0 | Z37: =+ROUND((V37)*(1+SUMIF($Y$2:$Y$4,X37,$Z$2:$Z$4)),0) -> 0
A38: RoofStruc | B38: =+B35 -> 3.2/2 | C38: 2.3.1.1 | D38: Pitched Roof | E38: m2 | H38: =+SUM(F38:G38) -> 0 | J38: =+I38*$J$5 -> 0 | L38: =+K38*$L$5 -> 0 | M38: =+J38+L38 -> 0 | N38: =+ROUND(M38*H38,2) -> 0 | O38: =N38 -> 0 | Q38: =+P38*$Q$5 -> 0 | S38: =+R38*$S$5 -> 0 | T38: =+Q38+S38 -> 0 | U38: =+ROUND(T38*H38,2) -> 0 | V38: =U38 -> 0 | X38: A | Y38: =+ROUND((O38)*(1+SUMIF($Y$2:$Y$4,X38,$Z$2:$Z$4)),0) -> 0 | Z38: =+ROUND((V38)*(1+SUMIF($Y$2:$Y$4,X38,$Z$2:$Z$4)),0) -> 0
A39: RoofStruc | B39: =+B38 -> 3.2/2 | C39: 2.3.1.2 | D39: Flat Roof | E39: m2 | H39: =+SUM(F39:G39) -> 0 | J39: =+I39*$J$5 -> 0 | L39: =+K39*$L$5 -> 0 | M39: =+J39+L39 -> 0 | N39: =+ROUND(M39*H39,2) -> 0 | O39: =N39 -> 0 | Q39: =+P39*$Q$5 -> 0 | S39: =+R39*$S$5 -> 0 | T39: =+Q39+S39 -> 0 | U39: =+ROUND(T39*H39,2) -> 0 | V39: =U39 -> 0 | X39: A | Y39: =+ROUND((O39)*(1+SUMIF($Y$2:$Y$4,X39,$Z$2:$Z$4)),0) -> 0 | Z39: =+ROUND((V39)*(1+SUMIF($Y$2:$Y$4,X39,$Z$2:$Z$4)),0) -> 0
A40: Roof | B40: =+B38 -> 3.2/2 | C40: 2.3.2 | D40: Roof Covering | H40: =+SUM(F40:G40) -> 0 | J40: =+I40*$J$5 -> 0 | L40: =+K40*$L$5 -> 0 | M40: =+J40+L40 -> 0 | N40: =+ROUND(M40*H40,2) -> 0 | O40: =N40 -> 0 | Q40: =+P40*$Q$5 -> 0 | S40: =+R40*$S$5 -> 0 | T40: =+Q40+S40 -> 0 | U40: =+ROUND(T40*H40,2) -> 0 | V40: =U40 -> 0 | X40: A | Y40: =+ROUND((O40)*(1+SUMIF($Y$2:$Y$4,X40,$Z$2:$Z$4)),0) -> 0 | Z40: =+ROUND((V40)*(1+SUMIF($Y$2:$Y$4,X40,$Z$2:$Z$4)),0) -> 0
...

Sheet Sec 4 - External Works
A1: Tender No: CE/25/T5/P/896 | L1: Generally | Q1: Markup
Q2: A | R2: 0.2
A3: SECTION 4 | Q3: B | R3: 0.1 | S3: PC rate
A4: DESIGN AND BUILD OF COASTAL DORMITORY EXPANSION FOR CHANGI EAST DEVELOPMENT | Q4: C
A6: CODE | B6: PAGE | C6: ITEM | D6: DESCRIPTION | E6: UNIT | F6: Material (S$) | G6: Labour (S$) | H6: U/RATE (S$) | I6: Phase A Qty | J6: Phase A Sub-Total | K6: Phase A Amount (S$) | L6: Phase B Qty | M6: Phase B Sub-Total | N6: Phase B Amount (S$) | O6: REMARKS | P6: MARKUP CODE | Q6: Phase A SUBMISSION AMOUNT (S$) | R6: Phase B SUBMISSION AMOUNT (S$)
A7: Ext | B7: 4.2/7 | D7: SECTION NO 4.2 — EXTERNAL WORKS | H7: =+SUM(F7:G7) -> 0 | J7: =+ROUND(I7*H7,2) -> 0 | K7: =SUM(J7:J7) -> 0 | M7: =+ROUND(L7*H7,2) -> 0 | N7: =SUM(M7:M7) -> 0 | P7: A | Q7: =+ROUND((K7)*(1+SUMIF($Q$2:$Q$4,P7,$R$2:$R$4)),0) -> 0 | R7: =+ROUND((N7)*(1+SUMIF($Q$2:$Q$4,P7,$R$2:$R$4)),0) -> 0
A8: Ext | B8: =+B7 -> 4.2/7 | C8: 1 | D8: SITE PREPARATION WORKS | H8: =+SUM(F8:G8) -> 0 | J8: =+ROUND(I8*H8,2) -> 0 | K8: =SUM(J8:J8) -> 0 | M8: =+ROUND(L8*H8,2) -> 0 | N8: =SUM(M8:M8) -> 0 | P8: A | Q8: =+ROUND((K8)*(1+SUMIF($Q$2:$Q$4,P8,$R$2:$R$4)),0) -> 0 | R8: =+ROUND((N8)*(1+SUMIF($Q$2:$Q$4,P8,$R$2:$R$4)),0) -> 0
A9: Ext | B9: =+B8 -> 4.2/7 | C9: 1.1 | D9: Site Clearance | H9: =+SUM(F9:G9) -> 0 | J9: =+ROUND(I9*H9,2) -> 0 | K9: =SUM(J9:J9) -> 0 | M9: =+ROUND(L9*H9,2) -> 0 | N9: =SUM(M9:M9) -> 0 | P9: A | Q9: =+ROUND((K9)*(1+SUMIF($Q$2:$Q$4,P9,$R$2:$R$4)),0) -> 0 | R9: =+ROUND((N9)*(1+SUMIF($Q$2:$Q$4,P9,$R$2:$R$4)),0) -> 0
A10: Ext | B10: =+B7 -> 4.2/7 | C10: 1.1.1 | D10: Provision of all machinery, equipment, labour, materials, tools including transportation for carting off excess earth and importing suitable earth necessary for the cut, fill, top up, consolidate and level up of existing ground to the proposed platform levels. | E10: Item | H10: =+SUM(F10:G10) -> 0 | J10: =+ROUND(I10*H10,2) -> 0 | K10: =SUM(J10:J10) -> 0 | M10: =+ROUND(L10*H10,2) -> 0 | N10: =SUM(M10:M10) -> 0 | P10: A | Q10: =+ROUND((K10)*(1+SUMIF($Q$2:$Q$4,P10,$R$2:$R$4)),0) -> 0 | R10: =+ROUND((N10)*(1+SUMIF($Q$2:$Q$4,P10,$R$2:$R$4)),0) -> 0
A11: Termite | B11: =+B10 -> 4.2/7 | C11: 1.1.2 | D11: Anti-termite treatment system to external areas. | E11: Item | H11: =+SUM(F11:G11) -> 0 | J11: =+ROUND(I11*H11,2) -> 0 | K11: =SUM(J11:J11) -> 0 | M11: =+ROUND(L11*H11,2) -> 0 | N11: =SUM(M11:M11) -> 0 | P11: A | Q11: =+ROUND((K11)*(1+SUMIF($Q$2:$Q$4,P11,$R$2:$R$4)),0) -> 0 | R11: =+ROUND((N11)*(1+SUMIF($Q$2:$Q$4,P11,$R$2:$R$4)),0) -> 0
A12: Earth | B12: =+B11 -> 4.2/7 | C12: 2 | D12: EARTHWORKS | H12: =+SUM(F12:G12) -> 0 | J12: =+ROUND(I12*H12,2) -> 0 | K12: =SUM(J12:J12) -> 0 | M12: =+ROUND(L12*H12,2) -> 0 | N12: =SUM(M12:M12) -> 0 | P12: A | Q12: =+ROUND((K12)*(1+SUMIF($Q$2:$Q$4,P12,$R$2:$R$4)),0) -> 0 | R12: =+ROUND((N12)*(1+SUMIF($Q$2:$Q$4,P12,$R$2:$R$4)),0) -> 0
A13: Earth | B13: =+B12 -> 4.2/7 | C13: 2.1 | D13: Excavation and Backfilling | H13: =+SUM(F13:G13) -> 0 | J13: =+ROUND(I13*H13,2) -> 0 | K13: =SUM(J13:J13) -> 0 | M13: =+ROUND(L13*H13,2) -> 0 | N13: =SUM(M13:M13) -> 0 | P13: A | Q13: =+ROUND((K13)*(1+SUMIF($Q$2:$Q$4,P13,$R$2:$R$4)),0) -> 0 | R13: =+ROUND((N13)*(1+SUMIF($Q$2:$Q$4,P13,$R$2:$R$4)),0) -> 0
A14: Earth | B14: =+B11 -> 4.2/7 | C14: 2.1.1 | D14: To carry out excavation and backfilling works to the required design platform levels of RL106.50. All fill material shall be properly graded to the required fall and compacted to the Minimum AASHTO density of 90% and any deviation in backfill material will subject to S.O. approval. All fill material shall conform to the Specifications and shall be subjected to the approval of the S.O. All fill material shall be supplied from the Contractor's own source, unless otherwise instructed by the S.O. | E14: Item | H14: =+SUM(F14:G14) -> 0 | J14: =+ROUND(I14*H14,2) -> 0 | K14: =SUM(J14:J14) -> 0 | M14: =+ROUND(L14*H14,2) -> 0 | N14: =SUM(M14:M14) -> 0 | P14: A | Q14: =+ROUND((K14)*(1+SUMIF($Q$2:$Q$4,P14,$R$2:$R$4)),0) -> 0 | R14: =+ROUND((N14)*(1+SUMIF($Q$2:$Q$4,P14,$R$2:$R$4)),0) -> 0
A15: Road | B15: =+B14 -> 4.2/7 | C15: 3 | D15: ROADS / PAVINGS WORKS | H15: =+SUM(F15:G15) -> 0 | J15: =+ROUND(I15*H15,2) -> 0 | K15: =SUM(J15:J15) -> 0 | M15: =+ROUND(L15*H15,2) -> 0 | N15: =SUM(M15:M15) -> 0 | P15: A | Q15: =+ROUND((K15)*(1+SUMIF($Q$2:$Q$4,P15,$R$2:$R$4)),0) -> 0 | R15: =+ROUND((N15)*(1+SUMIF($Q$2:$Q$4,P15,$R$2:$R$4)),0) -> 0
A16: Road | B16: =+B15 -> 4.2/7 | C16: 3.1 | D16: Roads, paths and pavings | H16: =+SUM(F16:G16) -> 0 | J16: =+ROUND(I16*H16,2) -> 0 | K16: =SUM(J16:J16) -> 0 | M16: =+ROUND(L16*H16,2) -> 0 | N16: =SUM(M16:M16) -> 0 | P16: A | Q16: =+ROUND((K16)*(1+SUMIF($Q$2:$Q$4,P16,$R$2:$R$4)),0) -> 0 | R16: =+ROUND((N16)*(1+SUMIF($Q$2:$Q$4,P16,$R$2:$R$4)),0) -> 0
A17: Road | B17: =+B14 -> 4.2/7 | C17: D | D17: To carry out road/paving works including Fire Engine Access and Carriageways, Traffic Ingress/Egress etc. as per design (all necessary road marking, directional signages and finishes are deemed to be included in the tender) complying to LTA standards, laid on graded aggregate base, sub-base and compacted earth sub-grade, all as specified in the drawings | E17: Item | H17: =+SUM(F17:G17) -> 0 | J17: =+ROUND(I17*H17,2) -> 0 | K17: =SUM(J17:J17) -> 0 | M17: =+ROUND(L17*H17,2) -> 0 | N17: =SUM(M17:M17) -> 0 | P17: A | Q17: =+ROUND((K17)*(1+SUMIF($Q$2:$Q$4,P17,$R$2:$R$4)),0) -> 0 | R17: =+ROUND((N17)*(1+SUMIF($Q$2:$Q$4,P17,$R$2:$R$4)),0) -> 0
A18: MiscExt | B18: =+B17 -> 4.2/7 | C18: 4 | D18: VEHICLE DOP/ BUS BAY WORKS | H18: =+SUM(F18:G18) -> 0 | J18: =+ROUND(I18*H18,2) -> 0 | K18: =SUM(J18:J18) -> 0 | M18: =+ROUND(L18*H18,2) -> 0 | N18: =SUM(M18:M18) -> 0 | P18: A | Q18: =+ROUND((K18)*(1+SUMIF($Q$2:$Q$4,P18,$R$2:$R$4)),0) -> 0 | R18: =+ROUND((N18)*(1+SUMIF($Q$2:$Q$4,P18,$R$2:$R$4)),0) -> 0
A19: MiscExt | B19: =+B18 -> 4.2/7 | C19: 4.1 | D19: Vehicle DOP/Bus Bay Works | H19: =+SUM(F19:G19) -> 0 | J19: =+ROUND(I19*H19,2) -> 0 | K19: =SUM(J19:J19) -> 0 | M19: =+ROUND(L19*H19,2) -> 0 | N19: =SUM(M19:M19) -> 0 | P19: A | Q19: =+ROUND((K19)*(1+SUMIF($Q$2:$Q$4,P19,$R$2:$R$4)),0) -> 0 | R19: =+ROUND((N19)*(1+SUMIF($Q$2:$Q$4,P19,$R$2:$R$4)),0) -> 0
A20: MiscExt | B20: =+B17 -> 4.2/7 | C20: 4.1.1 | D20: To construct bus bays for pickup/drop off including substructure and superstructure, sheltered linkways, rain shelters and benches. | E20: Item | H20: =+SUM(F20:G20) -> 0 | J20: =+ROUND(I20*H20,2) -> 0 | K20: =SUM(J20:J20) -> 0 | M20: =+ROUND(L20*H20,2) -> 0 | N20: =SUM(M20:M20) -> 0 | P20: A | Q20: =+ROUND((K20)*(1+SUMIF($Q$2:$Q$4,P20,$R$2:$R$4)),0) -> 0 | R20: =+ROUND((N20)*(1+SUMIF($Q$2:$Q$4,P20,$R$2:$R$4)),0) -> 0
A21: Collection | B21: =+B20 -> 4.2/7 | D21: To Collection: | J21: =SUM(J7:J20) -> 0 | K21: =SUM(K7:K20) -> 0 | M21: =SUM(M7:M20) -> 0 | N21: =SUM(N7:N20) -> 0 | P21: A | Q21: =SUM(Q7:Q20) -> 0 | R21: =SUM(R7:R20) -> 0
A22: Struct | B22: 4.2/8 | H22: =+SUM(F22:G22) -> 0 | J22: =+ROUND(I22*H22,2) -> 0 | K22: =SUM(J22:J22) -> 0 | M22: =+ROUND(L22*H22,2) -> 0 | N22: =SUM(M22:M22) -> 0 | P22: A | Q22: =+ROUND((K22)*(1+SUMIF($Q$2:$Q$4,P22,$R$2:$R$4)),0) -> 0 | R22: =+ROUND((N22)*(1+SUMIF($Q$2:$Q$4,P22,$R$2:$R$4)),0) -> 0
A23: Struct | B23: 4.2/8 | C23: 5 | D23: CONCRETE WORKS | H23: =+SUM(F23:G23) -> 0 | J23: =+ROUND(I23*H23,2) -> 0 | K23: =SUM(J23:J23) -> 0 | M23: =+ROUND(L23*H23,2) -> 0 | N23: =SUM(M23:M23) -> 0 | P23: A | Q23: =+ROUND((K23)*(1+SUMIF($Q$2:$Q$4,P23,$R$2:$R$4)),0) -> 0 | R23: =+ROUND((N23)*(1+SUMIF($Q$2:$Q$4,P23,$R$2:$R$4)),0) -> 0
A24: Struct | B24: =+B23 -> 4.2/8 | C24: 5.1 | D24: Concrete Works | E24: Item | H24: =+SUM(F24:G24) -> 0 | J24: =+ROUND(I24*H24,2) -> 0 | K24: =SUM(J24:J24) -> 0 | M24: =+ROUND(L24*H24,2) -> 0 | N24: =SUM(M24:M24) -> 0 | P24: A | Q24: =+ROUND((K24)*(1+SUMIF($Q$2:$Q$4,P24,$R$2:$R$4)),0) -> 0 | R24: =+ROUND((N24)*(1+SUMIF($Q$2:$Q$4,P24,$R$2:$R$4)),0) -> 0
A25: Struct | B25: =+B24 -> 4.2/8 | C25: 5.1.1 | D25: To construct concrete works such as slabs, footpaths, pavement, structure for multi-purpose hall hard courts, football/games pitches, outdoor fitness areas with all necessary painting and finishes. | E25: Item | H25: =+SUM(F25:G25) -> 0 | J25: =+ROUND(I25*H25,2) -> 0 | K25: =SUM(J25:J25) -> 0 | M25: =+ROUND(L25*H25,2) -> 0 | N25: =SUM(M25:M25) -> 0 | P25: A | Q25: =+ROUND((K25)*(1+SUMIF($Q$2:$Q$4,P25,$R$2:$R$4)),0) -> 0 | R25: =+ROUND((N25)*(1+SUMIF($Q$2:$Q$4,P25,$R$2:$R$4)),0) -> 0
A26: SignOthers | B26: =+B25 -> 4.2/8 | C26: 6 | D26: SIGNAGE | H26: =+SUM(F26:G26) -> 0 | J26: =+ROUND(I26*H26,2) -> 0 | K26: =SUM(J26:J26) -> 0 | M26: =+ROUND(L26*H26,2) -> 0 | N26: =SUM(M26:M26) -> 0 | P26: A | Q26: =+ROUND((K26)*(1+SUMIF($Q$2:$Q$4,P26,$R$2:$R$4)),0) -> 0 | R26: =+ROUND((N26)*(1+SUMIF($Q$2:$Q$4,P26,$R$2:$R$4)),0) -> 0
A27: SignOthers | B27: =+B26 -> 4.2/8 | C27: 6.1 | D27: Signage | E27: Item | H27: =+SUM(F27:G27) -> 0 | J27: =+ROUND(I27*H27,2) -> 0 | K27: =SUM(J27:J27) -> 0 | M27: =+ROUND(L27*H27,2) -> 0 | N27: =SUM(M27:M27) -> 0 | P27: A | Q27: =+ROUND((K27)*(1+SUMIF($Q$2:$Q$4,P27,$R$2:$R$4)),0) -> 0 | R27: =+ROUND((N27)*(1+SUMIF($Q$2:$Q$4,P27,$R$2:$R$4)),0) -> 0
A28: SignOthers | B28: =+B27 -> 4.2/8 | C28: 6.1.1 | D28: To supply and install all directional signages/traffic sign, mandatory signages required for TOP and obtaining FEDA licence, signboards and safety | E28: Item | H28: =+SUM(F28:G28) -> 0 | J28: =+ROUND(I28*H28,2) -> 0 | K28: =SUM(J28:J28) -> 0 | M28: =+ROUND(L28*H28,2) -> 0 | N28: =SUM(M28:M28) -> 0 | P28: A | Q28: =+ROUND((K28)*(1+SUMIF($Q$2:$Q$4,P28,$R$2:$R$4)),0) -> 0 | R28: =+ROUND((N28)*(1+SUMIF($Q$2:$Q$4,P28,$R$2:$R$4)),0) -> 0
A29: Soft | B29: =+B28 -> 4.2/8 | C29: 7 | D29: GRADING AND TURFING WORKS | H29: =+SUM(F29:G29) -> 0 | J29: =+ROUND(I29*H29,2) -> 0 | K29: =SUM(J29:J29) -> 0 | M29: =+ROUND(L29*H29,2) -> 0 | N29: =SUM(M29:M29) -> 0 | P29: A | Q29: =+ROUND((K29)*(1+SUMIF($Q$2:$Q$4,P29,$R$2:$R$4)),0) -> 0 | R29: =+ROUND((N29)*(1+SUMIF($Q$2:$Q$4,P29,$R$2:$R$4)),0) -> 0
A30: Soft | B30: =+B29 -> 4.2/8 | C30: 7.1 | D30: Grading and Turfing Works | E30: Item | H30: =+SUM(F30:G30) -> 0 | J30: =+ROUND(I30*H30,2) -> 0 | K30: =SUM(J30:J30) -> 0 | M30: =+ROUND(L30*H30,2) -> 0 | N30: =SUM(M30:M30) -> 0 | P30: A | Q30: =+ROUND((K30)*(1+SUMIF($Q$2:$Q$4,P30,$R$2:$R$4)),0) -> 0 | R30: =+ROUND((N30)*(1+SUMIF($Q$2:$Q$4,P30,$R$2:$R$4)),0) -> 0
A31: Soft | B31: =+B28 -> 4.2/8 | C31: 7.1.1 | D31: To grade and close turf all unpaved areas within the Contract boundary complete with necessary drainage and sumps (where required) | E31: m2 | H31: =+SUM(F31:G31) -> 0 | J31: =+ROUND(I31*H31,2) -> 0 | K31: =SUM(J31:J31) -> 0 | M31: =+ROUND(L31*H31,2) -> 0 | N31: =SUM(M31:M31) -> 0 | P31: A | Q31: =+ROUND((K31)*(1+SUMIF($Q$2:$Q$4,P31,$R$2:$R$4)),0) -> 0 | R31: =+ROUND((N31)*(1+SUMIF($Q$2:$Q$4,P31,$R$2:$R$4)),0) -> 0
A32: Soft | B32: =+B31 -> 4.2/8 | C32: 7.1.2 | D32: To re-grade and re-turf and reinstate all unpaved areas outside the Contract boundary disturbed in the process of the works. | E32: m2 | H32: =+SUM(F32:G32) -> 0 | J32: =+ROUND(I32*H32,2) -> 0 | K32: =SUM(J32:J32) -> 0 | M32: =+ROUND(L32*H32,2) -> 0 | N32: =SUM(M32:M32) -> 0 | P32: A | Q32: =+ROUND((K32)*(1+SUMIF($Q$2:$Q$4,P32,$R$2:$R$4)),0) -> 0 | R32: =+ROUND((N32)*(1+SUMIF($Q$2:$Q$4,P32,$R$2:$R$4)),0) -> 0
A33: Drain | B33: =+B32 -> 4.2/8 | C33: 8 | D33: DRAINAGE | H33: =+SUM(F33:G33) -> 0 | J33: =+ROUND(I33*H33,2) -> 0 | K33: =SUM(J33:J33) -> 0 | M33: =+ROUND(L33*H33,2) -> 0 | N33: =SUM(M33:M33) -> 0 | P33: A | Q33: =+ROUND((K33)*(1+SUMIF($Q$2:$Q$4,P33,$R$2:$R$4)),0) -> 0 | R33: =+ROUND((N33)*(1+SUMIF($Q$2:$Q$4,P33,$R$2:$R$4)),0) -> 0
A34: Drain | B34: =+B33 -> 4.2/8 | C34: 8.1 | D34: Drainage | E34: Item | H34: =+SUM(F34:G34) -> 0 | J34: =+ROUND(I34*H34,2) -> 0 | K34: =SUM(J34:J34) -> 0 | M34: =+ROUND(L34*H34,2) -> 0 | N34: =SUM(M34:M34) -> 0 | P34: A | Q34: =+ROUND((K34)*(1+SUMIF($Q$2:$Q$4,P34,$R$2:$R$4)),0) -> 0 | R34: =+ROUND((N34)*(1+SUMIF($Q$2:$Q$4,P34,$R$2:$R$4)),0) -> 0
A35: Drain | B35: =+B32 -> 4.2/8 | C35: 8.1.1 | D35: To design and construct, including all necessary markings, associated drainage for the open field to be functional and fit for purpose. | E35: Item | H35: =+SUM(F35:G35) -> 0 | J35: =+ROUND(I35*H35,2) -> 0 | K35: =SUM(J35:J35) -> 0 | M35: =+ROUND(L35*H35,2) -> 0 | N35: =SUM(M35:M35) -> 0 | P35: A | Q35: =+ROUND((K35)*(1+SUMIF($Q$2:$Q$4,P35,$R$2:$R$4)),0) -> 0 | R35: =+ROUND((N35)*(1+SUMIF($Q$2:$Q$4,P35,$R$2:$R$4)),0) -> 0
A36: Drain | B36: =+B35 -> 4.2/8 | D36: Surface drain; 300mm wide | E36: m | H36: =+SUM(F36:G36) -> 0 | J36: =+ROUND(I36*H36,2) -> 0 | K36: =SUM(J36:J36) -> 0 | M36: =+ROUND(L36*H36,2) -> 0 | N36: =SUM(M36:M36) -> 0 | P36: A | Q36: =+ROUND((K36)*(1+SUMIF($Q$2:$Q$4,P36,$R$2:$R$4)),0) -> 0 | R36: =+ROUND((N36)*(1+SUMIF($Q$2:$Q$4,P36,$R$2:$R$4)),0) -> 0
A37: Drain | B37: =+B36 -> 4.2/8 | D37: Surface drain; 600mm wide | E37: m | H37: =+SUM(F37:G37) -> 0 | J37: =+ROUND(I37*H37,2) -> 0 | K37: =SUM(J37:J37) -> 0 | M37: =+ROUND(L37*H37,2) -> 0 | N37: =SUM(M37:M37) -> 0 | P37: A | Q37: =+ROUND((K37)*(1+SUMIF($Q$2:$Q$4,P37,$R$2:$R$4)),0) -> 0 | R37: =+ROUND((N37)*(1+SUMIF($Q$2:$Q$4,P37,$R$2:$R$4)),0) -> 0
